Workbook

Sheet Overview
A1: Student Name | B1: MC Total (48) | C1: Q11 (12) | D1: Q12 (12) | E1: Q13 (16) | F1: Q16 (12) | G1: Essay Total (52) | H1: Grand Total (100) | I1: Percentage | J1: Letter Grade
A2: Melaud Shalikar | B2: 48 | C2: ='Q11_add_match'!G3 | D2: ='Q12_get_team_points'!H3 | E2: ='Q13_add_player_rating'!H3 | F2: ='Q16_pkg_team_tools'!G3 | G2: =SUM(C2:F2) | H2: =B2+G2 | I2: =H2/100 | J2: =IF(H2>=90,"A",IF(H2>=80,"B",IF(H2>=70,"C",IF(H2>=60,"D","F"))))
A3: Alyssa Kathryn Espino | B3: 48 | C3: ='Q11_add_match'!G4 | D3: ='Q12_get_team_points'!H4 | E3: ='Q13_add_player_rating'!H4 | F3: ='Q16_pkg_team_tools'!G4 | G3: =SUM(C3:F3) | H3: =B3+G3 | I3: =H3/100 | J3: =IF(H3>=90,"A",IF(H3>=80,"B",IF(H3>=70,"C",IF(H3>=60,"D","F"))))
A4: Alexis Garcia | B4: 33.333333 | C4: ='Q11_add_match'!G5 | D4: ='Q12_get_team_points'!H5 | E4: ='Q13_add_player_rating'!H5 | F4: ='Q16_pkg_team_tools'!G5 | G4: =SUM(C4:F4) | H4: =B4+G4 | I4: =H4/100 | J4: =IF(H4>=90,"A",IF(H4>=80,"B",IF(H4>=70,"C",IF(H4>=60,"D","F"))))
A5: Taylor Gensler | B5: 29.333333 | C5: ='Q11_add_match'!G6 | D5: ='Q12_get_team_points'!H6 | E5: ='Q13_add_player_rating'!H6 | F5: ='Q16_pkg_team_tools'!G6 | G5: =SUM(C5:F5) | H5: =B5+G5 | I5: =H5/100 | J5: =IF(H5>=90,"A",IF(H5>=80,"B",IF(H5>=70,"C",IF(H5>=60,"D","F"))))
A6: Joey Ha | B6: 46.666667 | C6: ='Q11_add_match'!G7 | D6: ='Q12_get_team_points'!H7 | E6: ='Q13_add_player_rating'!H7 | F6: ='Q16_pkg_team_tools'!G7 | G6: =SUM(C6:F6) | H6: =B6+G6 | I6: =H6/100 | J6: =IF(H6>=90,"A",IF(H6>=80,"B",IF(H6>=70,"C",IF(H6>=60,"D","F"))))
A7: Nathan Hoang | B7: 48 | C7: ='Q11_add_match'!G8 | D7: ='Q12_get_team_points'!H8 | E7: ='Q13_add_player_rating'!H8 | F7: ='Q16_pkg_team_tools'!G8 | G7: =SUM(C7:F7) | H7: =B7+G7 | I7: =H7/100 | J7: =IF(H7>=90,"A",IF(H7>=80,"B",IF(H7>=70,"C",IF(H7>=60,"D","F"))))
A8: Himanshu Ladole | B8: 44 | C8: ='Q11_add_match'!G9 | D8: ='Q12_get_team_points'!H9 | E8: ='Q13_add_player_rating'!H9 | F8: ='Q16_pkg_team_tools'!G9 | G8: =SUM(C8:F8) | H8: =B8+G8 | I8: =H8/100 | J8: =IF(H8>=90,"A",IF(H8>=80,"B",IF(H8>=70,"C",IF(H8>=60,"D","F"))))
A9: Sydney Mendez | B9: 29.333333 | C9: ='Q11_add_match'!G10 | D9: ='Q12_get_team_points'!H10 | E9: ='Q13_add_player_rating'!H10 | F9: ='Q16_pkg_team_tools'!G10 | G9: =SUM(C9:F9) | H9: =B9+G9 | I9: =H9/100 | J9: =IF(H9>=90,"A",IF(H9>=80,"B",IF(H9>=70,"C",IF(H9>=60,"D","F"))))
A10: Celest Moreira | B10: 48 | C10: ='Q11_add_match'!G11 | D10: ='Q12_get_team_points'!H11 | E10: ='Q13_add_player_rating'!H11 | F10: ='Q16_pkg_team_tools'!G11 | G10: =SUM(C10:F10) | H10: =B10+G10 | I10: =H10/100 | J10: =IF(H10>=90,"A",IF(H10>=80,"B",IF(H10>=70,"C",IF(H10>=60,"D","F"))))
A11: Michael Nguyen | B11: 48 | C11: ='Q11_add_match'!G12 | D11: ='Q12_get_team_points'!H12 | E11: ='Q13_add_player_rating'!H12 | F11: ='Q16_pkg_team_tools'!G12 | G11: =SUM(C11:F11) | H11: =B11+G11 | I11: =H11/100 | J11: =IF(H11>=90,"A",IF(H11>=80,"B",IF(H11>=70,"C",IF(H11>=60,"D","F"))))
A12: Thuy Tien Nguyen | B12: 46.666667 | C12: ='Q11_add_match'!G13 | D12: ='Q12_get_team_points'!H13 | E12: ='Q13_add_player_rating'!H13 | F12: ='Q16_pkg_team_tools'!G13 | G12: =SUM(C12:F12) | H12: =B12+G12 | I12: =H12/100 | J12: =IF(H12>=90,"A",IF(H12>=80,"B",IF(H12>=70,"C",IF(H12>=60,"D","F"))))
A13: Reyna Singh | B13: 48 | C13: ='Q11_add_match'!G14 | D13: ='Q12_get_team_points'!H14 | E13: ='Q13_add_player_rating'!H14 | F13: ='Q16_pkg_team_tools'!G14 | G13: =SUM(C13:F13) | H13: =B13+G13 | I13: =H13/100 | J13: =IF(H13>=90,"A",IF(H13>=80,"B",IF(H13>=70,"C",IF(H13>=60,"D","F"))))
... A32: Luis Ibarra | B32: 42.666667 | C32: ='Q11_add_match'!G33 | D32: ='Q12_get_team_points'!H33 | E32: ='Q13_add_player_rating'!H33 | F32: ='Q16_pkg_team_tools'!G33 | G32: =SUM(C32:F32) | H32: =B32+G32 | I32: =H32/100 | J32: =IF(H32>=90,"A",IF(H32>=80,"B",IF(H32>=70,"C",IF(H32>=60,"D","F"))))
A33: CLASS AVERAGE | B33: =AVERAGE(B2:B32) | C33: =AVERAGE(C2:C32) | D33: =AVERAGE(D2:D32) | E33: =AVERAGE(E2:E32) | F33: =AVERAGE(F2:F32) | G33: =AVERAGE(G2:G32) | H33: =AVERAGE(H2:H32) | I33: =AVERAGE(I2:I32)

Sheet Q11_add_match
A1: Q11_add_match — 12 points total
A2: Student Name | B2: Response | C2: A. Procedure header (2 pts) | D2: B. Validation logic (3 pts) | E2: C. INSERT statement (5 pts) | F2: D. Overall PL/SQL structure (2 pts) | G2: Total | H2: Notes
A3: Melaud Shalikar | B3: CREATE OR REPLACE PROCEDURE add_match( p_match_id NUMBER, p_season NUMBER, p_stage VARCHAR2, p_match_date DATE p_home_team_id NUMBER, p_away_team_id NUMBER ) IS BEGIN IF p_home_team_id = p_away_team_id THEN RAISE_APPLICATION_ERROR(-20001, 'Home and away teams cannot be the same'); END IF; INSERT INTO MATCHES ( match_id, season, stage, match_date, p_home_team_id, home_team_goal, away_team_goal ) p_away_team_id ) VALUES( match_id, season, stage, match_date, p_home_team_id, NULL, NULL ); END; / | C3: 1.5 | D3: 3 | E3: 3 | F3: 2 | G3: =SUM(C3:F3) | H3: Header: missing comma after p_match_date, p_season typed as NUMBER (should be VARCHAR2). Validation: correct check before INSERT, correct RAISE. INSERT: has structure but p_home_team_id in column list (should be home_team_id), p_away_team_id misplaced outside parens, VALUES uses column names not params. Goals=NULL correct. Structure OK.
A4: Alyssa Kathryn Espino | B4: CREATE OR REPLACE PROCEDURE add_match (p_match_id NUMBER, p_season NUMBER, p_stage VARCHAR2, p_match_date DATE, p_home_team_id NUMBER, p_away_team_id NUMBER) IS BEGIN IF p_home_team_id = p_away_team_id THEN RAISE_APPLICATION_ERROR (-20001, 'Teams cannot be similar'); END IF; INSERT INTO MATCHES VALUES(p_match_id, p_season, p_stage, p_match_date, p_home_team_id, p_away_team_id, NULL, NUL); END; | C4: 2 | D4: 3 | E4: 4 | F4: 2 | G4: =SUM(C4:F4) | H4: Header correct with 6 params. Validation correct before INSERT. INSERT uses VALUES shorthand without column list (risky but acceptable), NUL instead of NULL (typo). Structure clean.
A5: Alexis Garcia | B5: CREATE OR REPLACE PROCEDURE add_match(p_match_id, p_season, p_match_date, p_home_team_id, pp_away_team_id) | C5: 1 | D5: 0 | E5: 0 | F5: 0 | G5: =SUM(C5:F5) | H5: Header only — has procedure name and params but no datatypes, missing p_stage. No BEGIN, no validation, no INSERT, no END.
A6: Taylor Gensler | B6: CREATE OR REPLACE PROCEDURE add_match( p_match_id IN match.num%type p_season IN season.num%type p_stage IN stage.num%type p_match_date IN matchdate.num %type ) AS P_home_team_id := NULL p_away_team_id := NULL BEGIN SELECT hometeamid, awayteamid.hometeamgoal,away team goal Into vhometeam vawayteamid v homegaols v away goals FROM Matches Where match id = p match id If p_team_d = vhometeam an END IF IF v_home_goals = V_away_goals Then Return 1 ELSE IF p_team_id = v_gome_team and vhome goals > vaway goals OR p team id = away team is and v away goals > v home goals THEN Return 3 ELSE Return 0 END IF Exception WHEN NO DATA FOUND THEN END | C6: 1 | D6: 0 | E6: 0 | F6: 0.5 | G6: =SUM(C6:F6) | H6: Header has procedure name and some params but wrong datatypes (match.num%type doesnt exist), only 4 params. Confuses Q11 with Q12 — contains SELECT INTO and IF/ELSIF for win/draw/loss logic which belongs to the function question. No proper INSERT. No validation for same team. Has BEGIN/END structure.
A7: Joey Ha | B7: PROCEDURE add_match(match_id NUMBER, season VARCHAR2, stage NUMBER, match_date DATE, home_team_id NUMBER, away_team_id NUMBER) AS p_match_id matches.match_id%TYPE; p_season matches.season%TYPE; p_stage matches.stage%TYPE; p_match_date matches.match_date%TYPE; p_home_team_id matches.home_team_id%TYPE; p_away_team_id matches.away_team_id%TYPE; home_team_goal NULL; away_team_goal NULL; BEGIN IF p_home_team_id = p_away_team_id THEN RAISE_APPLICATION_ERROR(-20001, 'Same team cannot play itself'); END IF; INSERT INTO matches (match_id NUMBER, season VARCHAR2, stage NUMBER, match_date DATE, home_team_id NUMBER, away_team_id NUMBER) END add_match; | C7: 1.5 | D7: 3 | E7: 2 | F7: 1.5 | G7: =SUM(C7:F7) | H7: Header: missing CREATE OR REPLACE, params use column names not p_ prefix (match_id not p_match_id), then re-declares as %TYPE variables in body — confused approach. Validation correct. INSERT present but includes datatypes in column list (match_id NUMBER instead of match_id), no VALUES clause. Goals assigned as NULL in DECLARE but not inserted. Structure has BEGIN/END.
A8: Nathan Hoang | B8: CREATE OR REPLACE PROCEDURE add_match( p_match_id NUMBER, p_season NUMBER, p_stage NUMBER, p_match_date DATE, p_home_team_id NUMBER, p_away_team_id NUMBER, ) IS BEGIN IF p_home_team_id = p_away_team_id THEN RAISE_APPLICATION_ERROR(-20001, 'Teams cant be the same'); END IF; INSERT INTO MATCHES( match_id, season, stage, match_date, home_team_id, away_team_id, home_team_goal, away_team_goal ) VALUES( p_match_id, p_season, p_stage, p_match_date, p_home_team_id, p_away_team_id, NULL; END; | C8: 2 | D8: 3 | E8: 4 | F8: 2 | G8: =SUM(C8:F8) | H8: Header correct with 6 params. Trailing comma after last param. Validation correct before INSERT. INSERT: correct structure, all 8 cols listed, but VALUES missing closing entries — only shows NULL once (should be NULL, NULL). Missing closing paren. Structure clean with IS/BEGIN/END.
A9: Himanshu Ladole | B9: CREATE OR REPLACE PROCEDURE add_match ( p_match_id, p_season, p_stage, p_match_date, p_home_team_id, p_away_team_id ) AS BEGIN | C9: 1 | D9: 0 | E9: 0 | F9: 0.5 | G9: =SUM(C9:F9) | H9: Header: has params but no datatypes. Only BEGIN, no validation, no INSERT, incomplete.
A10: Sydney Mendez | B10: CREATE OR REPLACE PROCEDURE add_match( p_match_id IN MATCHES.match_id%TYPE, p_season IN MATCHES.season_id%TYPE, p_stage IN MATCHES.stage_id%TYPE, p_match_date IN MATCHES.date_id%TYPE, p_home_team_id IN MATCHES.home_team_idid%TYPE, p_away_team_id IN MATCHES.away_team_id%TYPE IS BEGIN IF p_home_team_id= P-away_team_id THEN RAISE_APPLICATION_ERROR(-20001, 'Home and away teams cannot be the same'); END IF; INSERT INTO MATCHES (match_id, season, stage, match_date, home_team, away_team | C10: 2 | D10: 2.5 | E10: 1 | F10: 1 | G10: =SUM(C10:F10) | H10: Header: uses %TYPE correctly, 6 params but some wrong column references (season_id, stage_id, date_id dont exist, home_team_idid typo). Validation: present but P-away (dash not underscore). INSERT: started but incomplete — cuts off mid-statement. Structure incomplete.
A11: Celest Moreira | B11: CREATE OR REPLACE PROCEDURE add_match( p_match_id NUMBER; p_season NUMBER; p_stage NUMBER; p_match_date DATE; p_home_team_id NUMBER; p_away_team_id NUMBER; ) IS BEGIN IF p_home_team_id = p_away_team_id THEN RAISE_APPLICATION_ERROR(-20001, ' A team cannot play itself'); END IF; INSERT INTO MATCHES( match_id, season, stage, match_date, home_team_id, away_team_id, home_team_goal, away_team_goal) VALUES( p_match_id, p_season, p_stage, p_match_date, p_home_team_id, p_away_team_id, NULL, NULL); END; / | C11: 1.5 | D11: 3 | E11: 5 | F11: 2 | G11: =SUM(C11:F11) | H11: Header: semicolons instead of commas between params. Validation correct. INSERT: perfect — all 8 cols, params correct, NULL for goals. Structure clean. Minor: semicolons in param list.
A12: Michael Nguyen | B12: CREATE OT REPLACE procedure add_match ( p_match_id number, p_season number, p_stage varchar2, p_match_date date, p_home_team_id number, p_away_team_id number) as BEGIN IF p_home_team_id = p_away_team_id then raise_applicatoin_error (-20001, 'teams cant be the same'); END IF; INSERT into matches values (p_match_id, p_season, p_stage, p_match_date, p_home_team_id, p_away_team_id, null); END; | C12: 1.5 | D12: 3 | E12: 3.5 | F12: 2 | G12: =SUM(C12:F12) | H12: Header: "CREATE OT REPLACE" typo, "raise_applicatoin_error" typo. Validation correct. INSERT: uses VALUES shorthand (no column list), but only 7 values (one NULL instead of two). Structure clean.
A13: Thuy Tien Nguyen | B13: CREATE OR REPLACE PROCEDURE add_match(home_team_goal, away_team_goal) AS v_home%TYPE; v_away%TYPE; BEGIN INSERT INTO MATCHES VALUES v_home, v_away; IF p_home_team_id = v_away_team_id THEN RAISE_APPLICATION_ERROR(-20001, 'Home team and Away team are the same!'); END IF; END; | C13: 0.5 | D13: 1 | E13: 1 | F13: 0.5 | G13: =SUM(C13:F13) | H13: Header: only 2 params (home_team_goal, away_team_goal — wrong params entirely). Validation: checks p_home = v_away (wrong variables). INSERT present but no column list, wrong values. Very confused overall.
A14: Reyna Singh | B14: CREATE OR REPLACE PROCEDURE add_match ( p_match_id IN MATCHES.match_id%TYPE, p_season IN MATCHES.match.season%TYPE, p_stage IN MATCHES.stage%TYPE, p_match_date IN MATCHES.match_date%TYPE, p_home_team_id IN MATCHES.home_team_id%TYPE, p_away_team_id IN MATCHES.away_team_id%TYPE) AS BEGIN IF p_home_team_id = p_away_team_id THEN RAISE_APPLICATION_ERROR(-20001, 'A team cannot play by itself'); INSERT INTO MATCHES ( match_id, season, stage, match_date, home_team_id, away_team_id, home_team_goal, away_team_goal, ) VALUES ( p_match_id, p_season, p_stage, | C14: 2 | D14: 2.5 | E14: 3 | F14: 1.5 | G14: =SUM(C14:F14) | H14: Header: %TYPE used well, "MATCHES.match.season%TYPE" wrong ref but intent clear. Validation: correct check but missing END IF before INSERT (runs together). INSERT: starts correctly with all 8 cols but VALUES section cut off — incomplete submission.
... A33: Luis Ibarra | B33: CREATE OR REPLACE PROCEDURE add_match( p_match_id NUMBER , p_season NUMBER , p_stage NUMBER , p_match_date DATE , p_home_team_id NUMBER , p_away_team_id NUMBER ) IS BEGIN IF p_home_team_id = p_away_team_id THEN RAISE_EAPPLICATION_ERROR(' Team cant play itslef'); END IF; INSERT INTO MATCHES ( match_id, season, stage, match_date, home_team_id, away_team_id, home_team_goal, away_team_goal) VALUES( p_match_id, p_season, p_stage, p_match_date, p_home_team_id, p_away_team_id, ) END; / | C33: 2 | D33: 2.5 | E33: 3.5 | F33: 2 | G33: =SUM(C33:F33) | H33: Header correct with 6 params. Validation: correct check, "RAISE_EAPPLICATION_ERROR" typo, missing error number (-20xxx). INSERT: correct 8 cols but VALUES missing last two (NULL, NULL) — trailing comma, no closing. Structure clean.

Sheet Q12_get_team_points
A1: Q12_get_team_points — 12 points total
A2: Student Name | B2: Response | C2: A. Function header & RETURN (2 pts) | D2: B. SELECT INTO (3 pts) | E2: C. Team validation (2 pts) | F2: D. Match exists & NULL check (2 pts) | G2: E. Win/draw/loss logic (3 pts) | H2: Total | I2: Notes
A3: Melaud Shalikar | B3: CREATE OR REPLACE FUNCTION get_team_points_for_match( p_match_id NUMBER, p_team_id NUMBER ) RETURN NUMBER IS v_home_team NUMBER; v_away_team NUMBER; v_home_goal NUMBER; v_away_goal NUMBER; BEGIN SELECT home_team_id, away_team_id, home_team_goal, away_team_goal INTO v_home_team, v_away_team, v_home_goal, v_away_goal FROM MATCHES WHERE match_id = p_match_id; IF p_team_id != v_home_team AND p_team_id != v_away_team THEN RAISE_APPLICATION_ERROR(-2002, 'Invalid team for this match'); END IF; IF v_home_goal IS NULL OR v_away_goal IS NULL THEN RAISE_APPLICATION_ERROR(-2003, 'Match not completed'); IF v_home_goal = v_away_goal THEN RETURN 1; ELSEIF(p_team_id = v_home_team AND v_home_goal > v_away_goal) OR(p_team_id = v_away_team And v_away_team > v_home_goal) THEN RETURN 3; ElSE RETURN 0; END IF; END; / | C3: 2 | D3: 3 | E3: 2 | F3: 1 | G3: 2 | H3: =SUM(C3:G3) | I3: Header+RETURN correct. SELECT INTO correct with all 4 cols. Team validation correct (!=...AND !=). Missing END IF on NULL check (only 1 validation complete). Win/draw/loss: draw correct, but ELSEIF instead of ELSIF, and away win logic compares v_away_team > v_home_goal (wrong var name, comparing team to goal). Error numbers -2002/-2003 outside valid range (-0.5).
A4: Alyssa Kathryn Espino | B4: *choosing l for my variable CREATE OR REPLACE FUNCTION get_team_points_for_match (p_match__id NUMBER, p_team_id NUMBER) RETURN NUMBER IS l_home_team_id NUMBER; l_away_team_id NUMBER; l_home_goals NUMBER; l_away__goals NUMBER; BEGIN SELECT home_team__id, away_team_id , home_team_goal, away_team_goal INTO l_home_team__id, l_away__team_id, l_home_goals; FROM MATCHES WHERE match_id = p_match__id; IF p_team_id != l_home__team_id and p_team_id != l_away_team_id THEN RAISE_APPLICATION_ERROR(-2001, 'Team not found in match'); END IF; IF l_home_goals = l_away_goals THEN RETURN 1; ELSIF p_team_id = l_home_team_id AND l_home__goals > l_away_goals THEN RETURN 3; ELSIF p_team_id = l_away_team_id AND l_away__goals > l_home_goals THEN RETURN 3; ELSE RETURN 0; END IF; END; | C4: 2 | D4: 2 | E4: 2 | F4: 0 | G4: 2.5 | H4: =SUM(C4:G4) | I4: Header correct, RETURN NUMBER. SELECT INTO present but missing l_away_goals in INTO clause (only 3 vars for 4 cols), double underscores in var names. Team check correct. No NULL goal check, no NO_DATA_FOUND handling. Win/draw/loss: draw=1 correct, distinguishes home vs away for win=3, but loss should be 0 not what is shown. Error -2001 outside range.
A5: Alexis Garcia | B5: CREATE OR REPLACE PROCEDURE get_team_points_for_match(p_match_id, p_team_id) | C5: 0 | D5: 0 | E5: 0 | F5: 0 | G5: 0 | H5: =SUM(C5:G5) | I5: Written as PROCEDURE not FUNCTION. Only header line with no body, no RETURN, no logic at all.
A6: Taylor Gensler | B6: CREATE OR REPLACE FUNCTION get_team_points_for_match p_match_ID number P_team_ID number ) Return number IS v_home_team_id MATCChes home_team_id%type v_away_team_d matches away_team_id%type BEGIN SELECT (hometeamid, awayteamid, hometeamgoal,awayteamgoal INTO v_hometeamid, vawayteamid, vhomegoals, v awaygoals FROM MATCHES WHERE match_id = team_id IF pteamid = hometeam id and pteamid = vawayteam id THEN raise_application_error (100'error') END IF IF v_home_goals = V_away_goals Then Return 1 ELSE IF p_team_id = v_gome_team and vhome goals > vaway goals OR p team id = away team is and v away goals > v home goals THEN Return 3 ELSE Return 0 END IF Exception WHEN NO DATA FOUND THEN END RETURN END | C6: 1 | D6: 1 | E6: 0 | F6: 1 | G6: 1 | H6: =SUM(C6:G6) | I6: Function header attempted but missing opening paren. SELECT INTO attempted but garbled column/var names. No team validation. Has NO_DATA_FOUND exception (1pt for match exists). Win/draw/loss logic attempted but messy, uses ELSE IF not ELSIF. Returns 3/1/0.
A7: Joey Ha | B7: CREATE OR REPLACE FUNCTION get_team_points_for_match(p_match_id NUMBER, p_team_id NUMBER) RETURN NUMBER AS f_team_points NUMBER; BEGIN IF p_match_id is NULL or p_match_id <= 0 THEN RAISE_APPLICATION_ERROR(-20001, 'MATCH NOT FOUND') END IF; IF p_team_id != home_team_id OR p_team_id != away_team_id THEN RAISE_APPLICATION_ERROR(-20002, 'ID NOT FOUND') END IF; IF home_team_goal IS NULL THEN RAISE_APPLICATION_ERROR(-20003, 'GAME NOT COMPLETE'); ELSIF away_team_goal IS NULL THEN RAISE_APPLICATION_ERROR(-20003, 'GAME NOT COMPLETE'); END IF; IF home_team_goal > away_team_goal THEN RETURN 3; ELSIF home_team_goal = away_team_goal THEN RETURN 1; ELSE home_team_goal < away_team_goal THEN RETURN 0; END get_team_points_for_match; | C7: 2 | D7: 0 | E7: 0 | F7: 1 | G7: 1 | H7: =SUM(C7:G7) | I7: Header and RETURN correct. No SELECT INTO — directly references column names without fetching. Team check uses OR instead of AND (wrong logic). NULL check for both goals present (1pt). Win/draw/loss attempted but only from home perspective, ELSE should not have THEN. Missing END IF.
A8: Nathan Hoang | B8: CREATE OR REPLACE FUNCTION get_team_points_for_match( p_match_id NUMBER, p_team_id NUMBER, ) RETURN NUMBER IS v_home_team_id NUMBER; v_away_team_id NUMBER; v_home_goals NUMBER; v_away_goals NUMBER; BEGIN SELECT home_team_id, away_team_id, home_team_goal, away_team_goal INTO v_home_team_id, v_away_team_id, v_home_goals, v_away_goals FROM MATCHES WHERE match_id = p_match_id; IF p_team_id = v_home_team_id AND p_team_id = v_away_team_id THEN RAISE_APPLICATION_ERROR(-20001, 'Team not a match'); IF v_home_goal IS NULL OR v_away_goal IS NULL THEN RAISE_APPLICATION_ERROR(-20002, 'Not finished'); END IF; IF v_home_goal = v_away_goal THEN RETURN 1; ELSIF (p_team_id = v_home_id AND v_home_goal > v_away_goal) OR (p_team_id = v_away_id AND v_away_goal > v_home_goal) THEN RETURN 3; ELSE RETURN 0; END; | C8: 2 | D8: 3 | E8: 1.5 | F8: 1.5 | G8: 3 | H8: =SUM(C8:G8) | I8: Header correct. SELECT INTO correct. Team check uses = AND = instead of NOT IN — logic checks if team IS BOTH teams (wrong direction, should be neither). Missing END IF after first IF. NULL check present with correct logic. Win/draw/loss: excellent — handles home vs away correctly with OR pattern. Missing END IF for some blocks. Variable names inconsistent (v_home_goal vs v_home_goals).
A9: Himanshu Ladole | B9: CREATE OR REPLACE FUNCTION get_team_points_for_match ( p_match_id IN NUMBER, p_team_id IN NUMBER ) RETUEN NUMBER IS v_home_team_id NUMBER; v_away_team_id NUMBER; v_home_team_goal NUMBER; v_away_team_goal NUMBER; BEGIN BEGIN SELECT home_team_id, away_team_id, home_team_goal, away_team_goal INTO v_home_team_id, v_away_team_id, v_home_team_goal, v_away_team_goal FROM MATCHES WHERE match_id = p_match_id; EXCEPTION WHEN NO_DATA_FOUND THEN RAISE_APPLICATION_ERROR(-20001, ' Match ID' || p_match_id || ' does not exist.'); END; IF p_team_id != v_home_team_id AND p_team_id != v_away_team_id THEN RAISE_APPLICATION_ERROR(-2000, ' Team ID' || p_team_id || ' does not particpate in this tournamnet.'); END IF; IF v_home_team_goal IS NULL OR v_away_team_goal IS NULL THEN RAISE_APPLICATION_ERROR(-20003, ' Match did not complete.'); END IF; IF v_home_team_goal = v_away_team_goal THEN RETURN 1; ELSIF (p_team_id = v_home_team_id AND v_home_team_goal > v_away_team_goal ) OR (p_team_id = v_away_team_id AND v_away_team_goal > v_home_team_goal ) THEN RETURN 3; ELSE RETURN 0; ENDIF; END; | C9: 1.5 | D9: 3 | E9: 2 | F9: 2 | G9: 3 | H9: =SUM(C9:G9) | I9: Header: RETUEN typo for RETURN, but otherwise correct. SELECT INTO: excellent with nested BEGIN/EXCEPTION for NO_DATA_FOUND. Team validation correct. NULL check correct. Win/draw/loss: excellent — handles home vs away with OR pattern. ENDIF missing space. Error -2000 for team check outside range.
A10: Sydney Mendez | B10: CREATE OR REPLACE FUNCTION get_team_points_ for_match( p_matxh_id IN NUMBER, p_team_id IN NUMBER ) RETURN NUMBER IS v_row MATCHES%ROWTYPE; BEGIN SELECT * INTO v_row FROM MATCHES WHERE match_id = p_match_id; IF p_team_id != v_row.home_team_id AND p_team_id != v_row.away_team_id THEN RAISE_APPLICATION_ERROR(-20001, 'Team not in match.'); END IF; IF v_row.home_team_goal = v_row.away_team_goal THEN RETURN 1; ELSEIF (p_team_id = v_row.home_team_id AND v_row.home_team_goal > v_row.away_team_goal) OR (p_team_id = v_row.away_team_id AND v_row.away_team_goal > v_row.home_team_goal) THEN RETURN 3; ELSE RETURN 0; END IF; EXCEPTION WHEN NO_DATA_FOUND THEN RAISE_APPLICATION_ERROR(-2003, 'match not found'); END get_team_points_for_match; / | C10: 2 | D10: 2.5 | E10: 2 | F10: 1.5 | G10: 2.5 | H10: =SUM(C10:G10) | I10: Header: space in function name "get_team_points_ for_match", matxh typo, but RETURN NUMBER correct. SELECT INTO: uses %ROWTYPE approach (correct). Team check correct. No NULL goal check explicitly but has it implicitly (incomplete). ELSEIF instead of ELSIF. Win/draw/loss handles home and away correctly. NO_DATA_FOUND in EXCEPTION block but error -2003 outside range.
A11: Celest Moreira | B11: CREATE OR REPLACE FUNCTION get_team_points_for_match( p_match_id NUMBER, p_team_id NUMBER ) RETURN NUMBER IS v_home_team_id MATCHES.home_team_id%TYPE; v_away_team_id MATCHES.away_team_id%TYPE; v_home_goals MATCHES .home_team_goal%TYPE; v_away_goals MATCHES.home_team_goal%TYPE; BEGIN SELECT home_team_id, away_team_id, home_team_goal, away_team_goal INTO v_home_team_id, v_away_team_id, v_home_goals, v_away_goals FROM MATCHES WHERE match_id = p_match_id; IF p_team_d != v_home_team_id AND p_team_id != v_away_team_id THEN RAISE_APPLICATION_ERROR (-2002, 'Team not part of this match'); END IF; IF v_home_goals = v_away_goals THEN RETURN 1; ELSIF (p_team_id = v_home_team_id AND v_home_goals > v_away_goals) OR (p_team_id = v_away_team_id AND v_away_goals > v_home_goals) THEN RETURN 3; ELSE RETURN 0; END IF; EXCEPTION WHEN NO_DATA_FOUND THEN RAISE_APPLICATION_ERROR(-20001, 'Match does not exist'); END; / | C11: 2 | D11: 3 | E11: 2 | F11: 1 | G11: 3 | H11: =SUM(C11:G11) | I11: Header correct. SELECT INTO correct with %TYPE vars. Team check: "p_team_d" typo but logic correct. Error -2002 outside range. No explicit NULL check for goals. Win/draw/loss: excellent — handles home vs away. NO_DATA_FOUND exception handler.
A12: Michael Nguyen | B12: create or replace function get_team_point_for_match (p_match_id number, p_team_id number) return number as v_home_id matches.home_team_id%TYPE; v_away_id matches.away_team%TYPE; v_home_goal matches.home_team_goal%TYPE; v_away_goal Matches.away_team_goal%TYPE; begin select home_team_id, away_team_id, home_team_goal, away_team_goal into v_home_id, v_away_id, v_home_goal, v_away_goal from matches where matches_id = p_match_id IF p_team_id =! v_home_id and p_team_id != v_away_id then raise_application_error(-20001, 'invalid team'); end if ; IF v_home_goal IS NULL OR v_away_goal IS NULL THEN raise_application_error(-20002, 'Match not complete'); IF v_home_goal = v_away_goal THEN return 1; ELSIF p_team_id = v_home_id AND v_home_goal > v_away_goal THEN RETURN 3; ELSIF p_team_id = v_away_id AND v_away_goal > v_home_goal THEN RETURN 0; end if; END; | C12: 2 | D12: 3 | E12: 2 | F12: 2 | G12: 2 | H12: =SUM(C12:G12) | I12: Header: "get_team_point_for_match" (missing s). SELECT INTO correct. Team check: "=!" instead of "!=" but intent clear. NULL check present. Win/draw/loss: handles home correctly but away returns 0 instead of 3 for away win. Missing semicolons, missing END IFs.
A13: Thuy Tien Nguyen | B13: CREATE OR REPLACE FUNCTION get_team_points_for_match(p_match_id, p_team_id) RETURN NUMBER AS v_home_team_goal NUMBER; v_away_team_goal NUMBER; BEGIN SELECT ml.match_id, ml.team_id, m.home_team_id, m.away_team_id FROM match_lineup ml INNER JOIN matches m ON p_match_id = v_match; IF v_home_team_goal > v_away_team_goal THEN DBMS_OUTPUT.PUT_LINE('Home win'); RETURN 1; ELSIF v_home_team_goal = v_away_team_goal THEN DBMS_OUTPUT.PUT_LINE('Draw'); RETURN 0; ELSE DBMS_OUTPUT.PUT_LINE('Away win'); RETURN 3; END IF; END; | C13: 1 | D13: 1 | E13: 0 | F13: 0 | G13: 1 | H13: =SUM(C13:G13) | I13: Header: params missing datatypes, RETURN NUMBER present. SELECT: attempts JOIN but no INTO, wrong tables/logic. No team validation. No NULL check. Win/draw/loss attempted but returns wrong values (1 for win, 0 for draw, 3 for loss — reversed).
A14: Reyna Singh | B14: CREATE OR REPLACE FUNCTION get_team_points_for_match ( p_match_id MATCHES.match_id%TYPE p_team_id TEAM.team_id%TYPE ) RETURN NUMBER AS v_home_team_id MATCHES.home_team_id%TYPE; v_away_team_id MATCHES.away_team_id%TYPE; v_home_goal MATCHES.home_team_goal%TYPE; v_away_goal MATCHES.away_team_goal%TYPE; BEGIN SELECT home_team_id, away_team_id, home__team_goal, away_team_goal INTO v_hometeam_id, v__away_team_id, v_home_goal, v_away_goal FROM MATCHES WHERE match_id = p_match_id; IF p_team_id != v_home_team_id AND p_team_id != v_away_team_id THEN RAISE_APPLICATION_ERROR(-20001, 'Invalid team for this match'); IF v_home_goal IS NULL OR v_away_goal IS NULL THEN RAISE_APPLICATION_ERROR(-20002, 'Match not completed'); END IF; IF v_home_goal = v_away_goal THEN RETURN1; ELSIF p_team_id = v_home_team_id AND v_home_goal > v_away_goal THEN RETURN 3; ELSIF p_team__id = v_away_team_id AND v_away_goal > v_home_goal THEN RETURN 3; ELSE RETURN 0; END IF; EXCEPTION WHEN NO_DATA_FOUND THEN RAISE_APPLICATION_ERROR(-20003, 'Match not found'); END; | C14: 2 | D14: 3 | E14: 2 | F14: 2 | G14: 3 | H14: =SUM(C14:G14) | I14: Header correct with %TYPE. SELECT INTO correct. Team check correct but missing END IF. NULL check present. Win/draw/loss: handles both home and away correctly (returns 3 for both). RETURN1 missing space. NO_DATA_FOUND exception. Solid overall despite minor syntax.
... A30: Ian Kim | B30: CREATE PROCEDURE get_team_points_for_match( p_match_id.snum%TYPE, p_team_id.snum%TYPE v_count MATCHES; BEGIN SELECT COUNT(*) INTO v_count FROM Matches WHERE snum=p_snum AND matchnum= p_team_id; IF v_count = 0 THEN RAISE_APPLICATION_ERROR 'Match not played' || p_team_id; END; / -- FUNCTION CREATE OR REPLACE FUNCTION get_match_points (p_match_id) RETURN VARCHAR2 AS BEGIN RETURN CASE WHEN home_team_goal> away_team_goal THEN 'home team 3 pts' WHEN away_team_goal> home_team_goal THEN 'away team 3 pts' WHEN home_team_goal<away_team_goal THEN 'home team 0 pts' WHEN away_team_goal<home_team_goal THEN 'away team 0 pts' WHEN home_team_goal=away_team_goal THEN 'home team 1 pts' WHEN home_team_goal=away_team_goal THEN 'away team 1 pts' ELSEIF REJECT NULL = "Match incompleted END; / | C30: 1 | D30: 0 | E30: 0.5 | F30: 0.5 | G30: 1 | H30: =SUM(C30:G30) | I30: Header: CREATE PROCEDURE (not FUNCTION), params use wrong references. Two attempts: first as procedure with COUNT validation, second as FUNCTION with CASE — better. CASE handles win/draw correctly but redundant conditions. NULL rejection attempted but garbled. No proper SELECT INTO.
A31: Taylor Lewis | C31: 0 | D31: 0 | E31: 0 | F31: 0 | G31: 0 | H31: =SUM(C31:G31) | I31: Empty submission.
A32: Ronald Portillo Quinteros | B32: CREATE OR REPLACE FUNTION get_team_points_match(p_match_id,p_team_id NUMBER) RETURN VARCHAR 2 AS BEGIN IF p_match_id IS NULL THEN RETURN 'Reject the call'; ELSIF p_team_id =<not equal> home_team_id OR away_team_id THEN RETURN 'Reject the call'; ELSIF home_team_goal OR away_team_goal = NULL THEN RETURN ' reject call because match is nor completet'; ELSE RETURN '3' FOR W, '1' FOR D, '0' FOR 'L' END IF; END; | C32: 0.5 | D32: 0 | E32: 0.5 | F32: 0.5 | G32: 0 | H32: =SUM(C32:G32) | I32: Header: "FUNTION" typo, RETURN VARCHAR2 (wrong type). No SELECT INTO. NULL check attempted but garbled. Team check attempted. Win/draw/loss: just returns string literals, not numbers.
A33: Luis Ibarra | B33: CREATE OR REPLACE FUNCTION get_team_points_for_match (p_match_id NUMBER, p_team_id NUMBER) RETURN NUMBER IS v_match_results NUMBER v_home_matches v_away_matches BEGIN IF v_home_matches > 3 THEN dbms_ouput.put_line (v_match_results || 'Home team wins') ELSE IF v_away_matches > 3 THEN dbms_ouput.put_line (v_match_results || 'Away team wins') ELSE dbms_ouput.put_line (v_match_results || 'Game Draw') END IF; RETURN v_match_results END; / | C33: 2 | D33: 0 | E33: 0 | F33: 0 | G33: 0.5 | H33: =SUM(C33:G33) | I33: Header: FUNCTION correct, RETURN NUMBER. No SELECT INTO — variables declared but never populated. Win/draw/loss: compares v_home_matches > 3 (wrong concept — should compare goals). Returns v_match_results but never assigned properly.

Sheet Q13_add_player_rating
A1: Q13_add_player_rating — 16 points total
A2: Student Name | B2: Response | C2: A. Procedure header (3 pts) | D2: B. INSERT statement (5 pts) | E2: C. Cursor declaration (3 pts) | F2: D. Cursor loop/fetch (3 pts) | G2: E. DBMS_OUTPUT (2 pts) | H2: Total | I2: Notes
A3: Melaud Shalikar | B3: CREATE OR REPLACE PROCEDURE add_playerr_rating( p_player_id NUMBER, p_attribute_date DATE, p_overall_rating NUMBER ) IS CURSOR c_ratings IS SELECT attributes_date, overall_rating FROM PLAYER_ATTRIBUTE_HISTORY WHERE player_id = p_player_id ORDER BY attribute_date DESC; BEGIN INSERT INTO PLAYER_ATTRIBUTE_HISTORY( player_id, attribute_date, overall_rating ) VALUES( p_player_id, p_attribute_date, p_overall_rating ); FOR rec IN c_ratings LOOP DBMS_OUTPUT.PUT_LINE(rec.attribute_date || '' || rec.overall_rating); END LOOP; END; / | C3: 2 | D3: 5 | E3: 2.5 | F3: 3 | G3: 2 | H3: =SUM(C3:G3) | I3: Header: typo "add_playerr_rating", only 3 params (missing potential, preferred_foot, player_attr_id) but minimum met. INSERT: correct 3-col insert. Cursor: has WHERE and ORDER BY DESC but "attributes_date" typo in SELECT (should be attribute_date). Loop: FOR rec IN c_ratings correct. Output: PUT_LINE with both fields.
A4: Alyssa Kathryn Espino | B4: CREATE OR REPLACE PROCEDURE add_player_rating (p__player_id NUMBER, p_attribute__date DATE, p__overall_rating NUMBER) IS BEGIN INSERT INTO PLAYER_ATTRIBUTE_HISTORY (player_id, attribute_date, overall__rating) VALUES (p_player_id, p_attribute_date, p_overall_rating); FOR rec IN (SELECT attribute_date, overall_rating FROM PLAYER_ATTRIBUTE _HISTORY WHERE player_id = p_player_id ORDER BY attribute_date DESC) LOOP dmbs_output.put_line (rec.attribute_date || ' ' || rec.overall__rating); END LOOP; END add_player_rating; | C4: 2 | D4: 4 | E4: 3 | F4: 3 | G4: 1 | H4: =SUM(C4:G4) | I4: Header: 3 params with double underscores (typos). INSERT correct but "overall__rating" typo. Cursor: implicit FOR LOOP with WHERE and ORDER BY DESC — correct. Loop: correct FOR rec pattern. Output: "dmbs_output.put_line" misspelling, and "overall__rating" typo, but intent clear.
A5: Alexis Garcia | B5: CREATE OR REPLACE PROCEDURE add_player_rating CURSOR c_ratings (p_pid NUMBER) IS SELECT attribute_date, overall_rating FROM PLAYER_ATTRIBUTE_HISTORY WHERE player_id = p_pid ORDER BY attribute_date DESC; | C5: 0 | D5: 0 | E5: 2 | F5: 0 | G5: 0 | H5: =SUM(C5:G5) | I5: No proper procedure header (no params in parens, no IS/BEGIN). No INSERT. Cursor declaration is actually correct (parameterized, correct table, WHERE, ORDER BY DESC). But no loop, no output.
A6: Taylor Gensler | B6: CREATE OR REPLACE PROCEDURE add_player_rating p_player_id NUMBER p_attribute_date DATE p_overall_rating NUMBER ) IS CURSOR c_rating_history IS SELECT attribute_date, over_rating FROM PLAYER_ATTRIVUTE_HISTORY( player_ID, attribute_date, overall_raating ) VALUES( p_player_id, p_attribute_date, p_overall_rating); FOR rec IN c_rating_history LOOP DBMS_OUTPUT_LINE ('Date' || TO_CHAR (rec.attrivute_date 'date' || ' |Overall Rating ' || rec.overall_rating); END LOOP; END; / | C6: 1 | D6: 0 | E6: 1 | F6: 1 | G6: 0.5 | H6: =SUM(C6:G6) | I6: Header has procedure name and 3 params but missing opening paren. No INSERT statement (jumps to cursor). Cursor attempted but SELECT columns garbled, FROM has wrong table syntax. Loop: FOR rec pattern present. Output: DBMS_OUTPUT_LINE (wrong name) but intent visible.
A7: Joey Ha | B7: PROCEDURE add_player_rating ( p_overall_rating NUMBER) AS v_overall_rating player_attribute_history.overall_rating%TYPE; BEGIN INSERT INTO player_attribute_history (overall_rating) VALUES (p_overall_rating, NUMBER) CURSOR c_player IS SELECT DISTINCT player_id FROM player_attribute_history; BEGIN open c_player; loop UPDATE player_attribute_history SET overall_rating WHERE c_player_id; DBMS_OUTPUT.PUT_LINE('Player' || c_player_id || 'Rating" || c_overall_rating ) | C7: 1 | D7: 1 | E7: 0 | F7: 0 | G7: 0.5 | H7: =SUM(C7:G7) | I7: Header: only 1 param (p_overall_rating), missing player_id. INSERT INTO correct table but only 1 column. Cursor: c_player selects DISTINCT player_id — wrong concept (should be rating history). Loop: uses UPDATE instead of printing. Output: PUT_LINE attempted but garbled.
A8: Nathan Hoang | B8: CREATE OR REPLACE PROCEDURE add_player_rating ( p_player_id NUMBER, p_attribute _date DATE, p_overall_rating NUMBER ) IS CURSOR C IS SELECT attribute_date, overall_rating FROM PLAYER_ATTRIBUTE_HISTORY WHERE player_id = p_player_id ORDER BY attribute_date DESC; BEGIN INSERT INTO PLAYER_ATTRIBUTE_HISTORY (player_id, attribute_date, overall_rating) VALUES (p_player_id, p_attribute_date, p_overall_rating); FOR r IN c LOOP dbms_output.put_line(r.attribute_date || ' ' || r.overall_rating); END LOOP; END; | C8: 2.5 | D8: 5 | E8: 3 | F8: 3 | G8: 2 | H8: =SUM(C8:G8) | I8: Header: 3 params, space in "p_attribute _date" typo but otherwise correct. INSERT correct. Cursor: correct with WHERE and ORDER BY DESC. FOR LOOP correct. Output: correct with both fields.
A9: Himanshu Ladole | B9: CREATE OR REPLACE PROCEDURE add_player_rating ( p_player_id IN PLAYER_ATTRIBUTE_HISTORY.player_id%TYPE, p_attribute_date IN PLAYER_ATTRIBUTE_HISTORY.attribute_date%TYPE , p_overall_rating IN PLAYER_ATTRIBUTE_HISTORY.overall_rating%TYPE) AS CURSOR c_rating IS SELECT atrribute_date. overall_rating FROM PLAYER_ATTRIBUTE_HISTORY WHERE player_id = p_player_id ORDER BY attribute_date DESC; BEGIN INSERT INTO PLAYER_ATTRIBUTE_HISTORY (player_id,attribute_date, overall_rating) VALUES (p_player_id,p_attribute_date, p_overall_rating) dbms.outline_put.line ('Rating hisotory of player ID' || p_player_id); r_history c_rating%ROWTYPE; OPEN c_rating; LOOP FETCH c_rating INTO r_history; EXIT WHEN c_rating%NOTFOUND; dbms.outline_put.line ('Date -' ||r_history.attribute_date || ' Rating -'); END LOOP; CLOSE c_rating; EXCEPTION WHEN OTHERS THEN dbms.outline_put.line ('error' || SQLERM); IF c_rating%ISOPEN THEN CLOSE c_rating; END IF; END; | C9: 3 | D9: 4 | E9: 2.5 | F9: 2.5 | G9: 1 | H9: =SUM(C9:G9) | I9: Header: uses %TYPE correctly, 3 params. INSERT correct but missing semicolon. Cursor: has WHERE and ORDER BY DESC but "atrribute_date." (period instead of comma) in SELECT. OPEN/FETCH/CLOSE pattern — correct structure. Output: "dbms.outline_put.line" (badly wrong name) but intent clear, and missing overall_rating in the second PUT_LINE.
A10: Sydney Mendez | C10: 0 | D10: 0 | E10: 0 | F10: 0 | G10: 0 | H10: =SUM(C10:G10) | I10: Empty submission — no response.
A11: Celest Moreira | B11: CREATE OR REPLACE PROCEDURE add_player_rating( p_player_id NUMBER, p_attribute_date DATE; p_overall_rating NUMBER ) IS CURSOR c_rating_history IS SELECT attribute_date, over_rating FROM PLAYER_ATTRIBUTE_HISTORY WHERE player_id = p_player_id ORDER BY attribute_date DESC; BEGIN INSERT INTO PLAYER_ATTRIBUTE_HISTORY( player_id, attribute_date, overall_rating ) VALUES( p_player_id, p_attribute_date, p_overall_rating); FOR rec IN c_rating_history LOOP DBMS_OUTPUT.PUT_LINE( 'Date: ' || TO_CHAR (rec.attribute_date, 'YYYY-MM-DD') || ' | Overall Rating: ' || rec.overall_rating); END LOOP; END; / | C11: 2.5 | D11: 5 | E11: 2.5 | F11: 3 | G11: 2 | H11: =SUM(C11:G11) | I11: Header: semicolons mixed with commas in params but 3 params correct. INSERT correct. Cursor: "over_rating" typo in SELECT but has WHERE and ORDER BY DESC. FOR LOOP correct. Output: excellent with TO_CHAR formatting.
A12: Michael Nguyen | B12: CREATE OR REPLACE PROCEDURE and_player_rating (p_player_id NUMBER, p_attribute_date DATE, p_overall_rating NUMBER) AS BEGIN INSERT into PLAYER_ATTRIBUTE_HISTORY VALUES (p_player_id, p_attribute_date, p_overall_rating); FOR rec IN ( SELECT attribute_date, overall_rating FROM PLAYER_ATTRIBUTE_HISTORY WHERE player_id = p_player_id ORDER by attribute_date = DESC LOOP DBMS_OUTPUT.PUT_LINE( rec.attribute_date || ' ' || rec.overall_rating); END LOOP; END; | C12: 2 | D12: 3 | E12: 3 | F12: 3 | G12: 2 | H12: =SUM(C12:G12) | I12: Header: "and_player_rating" typo. INSERT uses VALUES shorthand (acceptable). Cursor: implicit FOR LOOP, correct table, WHERE, ORDER BY (has "= DESC" instead of just DESC). Loop and output correct.
A13: Thuy Tien Nguyen | B13: INSERT INTO player_attribute_history VALUES attribute_rate, overall_rating; CREATE OR REPLACE PROCEDURE add_player_rating(p_attribute_rate, p_overall_rating) AS CURSOR c_ratings (p_pid NUMBER) IS SELECT pah.attribute_date, pah.overall_rating FROM PLAYER_ATTRIBUTE_HISTORY pah WHERE player_id = p_pid ORDER BY attribute_date DESC; v_attribute_rate pah.attribute_rate%TYPE; v_overall_rating pah.overall_rating%TYPE; BEGIN OPEN c_rating; LOOP FETCH c_rating INTO v_attribute_rate, v_overall_rating; EXIT WHEN c_rating%NOTFOUND; dbms_output.put_line('Attribute date is: ' | | v_attribute_date); dbms_output.put_line('Overall rate is: ' | | v_overall_rating); END LOOP; END c_rating; END; | C13: 1.5 | D13: 0 | E13: 2.5 | F13: 2 | G13: 1.5 | H13: =SUM(C13:G13) | I13: INSERT is outside the procedure (before CREATE). Procedure has cursor correctly parameterized with WHERE and ORDER BY DESC. OPEN/FETCH/CLOSE pattern attempted — mostly correct but "END c_rating" instead of "CLOSE c_rating". Output present with both fields but "| |" spacing.
A14: Reyna Singh | B14: CREATE OR REPLACE PROCEDURE add_player_rating( p_player_id NUMBER, p_attribute_date DATE, p_overall_rating NUMBER) AS CURSOR c_rating_history AS SELECT attribute_date, overall_rating FROM PLAYER_ATTRIBUTE_HISTORY WHERE player_id = p_player_id ORDER BY attribute_date DESC; BEGIN INSERT INTO PLAYER_ATTRIBUTE_HISTORY (player_attr_id, player_id, attribute_date, overall_rating) VALUES (PLAYER_ATTR_SEQ.NEXTVAL, p_player_id, p_attribute_date, p_overall_rating); FOR rec IN c_rating_history LOOP DBMS_OUTPUT.PUT_LINE( rec.attribute_date || ' - ' || rec.overall_rating); END LOOP; END; | C14: 3 | D14: 5 | E14: 2.5 | F14: 3 | G14: 2 | H14: =SUM(C14:G14) | I14: Header correct. INSERT excellent — includes NEXTVAL for PK. Cursor: "c_rating_history AS" should be IS, but correct SELECT with WHERE and ORDER BY DESC. FOR LOOP correct. Output correct.
A15: Wayne Wilhelm | B15: CREATE OR REPLACE PROCEDURE add_player_rating IN PLAYER_ATTRIBUTE_HISTORY (add_player_rating) p_param1 attribute_date p_pram2 overall_rating AS BEGIN END; | C15: 0.5 | D15: 0 | E15: 0 | F15: 0 | G15: 0 | H15: =SUM(C15:G15) | I15: Header severely garbled — "add_player_rating IN PLAYER_ATTRIBUTE_HISTORY". Wrong param names. No INSERT. No cursor. No loop. No output. Just BEGIN/END with nothing inside.
A16: Nicholas Nguyen | B16: CREATE OR REPLACE PROCEDURE add_player_rating ( p_player_id PLAYER.player_id%TYPE, p_player_attr_id PLAYER_ATTRIBUTE_HISTORY.player_attr_id%TYPE ) AS v_attribute_date PLAYER_ATTRIBUTE_HISTORY%TYPE; v_overall_rating PLAYER_ATTRIBUTE_HISTORY%TYPE; CURSOR c_player_rating IS ( SELECT attribute_date, overall_rating FROM PLAYER_ATTRIBUTE_HISTORY ORDER BY attribute_date DESC; ) BEGIN INSERT INTO PLAYER_ATTRIBUTE_HISTORY(player_attr_id, player_id) VALUES(p_player_attr_id, p_player_id); OPEN c_player_rating LOOP FETCH c_player_rating INTO v_attribute_date, v_overall_rating EXIT WHEN NO_DATA_FOUND; dbms_output.put_line('Player ID: ' || p_player_id ||' Attribute Date: '|| v_attribute_date || ' Overall Rating: ' || v_overall_rating); END; -- will insert into player attribute history table with params (player_attr_id PK and player_id), rest of values may be null. -- after insertion for ONE row, procedure will loop to print all records in PLAYER_ATTRIBUTE_HISTORY table until no data is found. | C16: 1.5 | D16: 2 | E16: 2 | F16: 2 | G16: 2 | H16: =SUM(C16:G16) | I16: Header: 2 params only (player_id, player_attr_id — missing date, rating). INSERT: only 2 columns. Cursor: missing WHERE clause (gets all players). OPEN/FETCH/CLOSE pattern attempted correctly. Output correct with 3 fields. Comments show understanding.
A17: Anthony Sierra | B17: --CREATE--- CREATE OR REPLACE PROCEDURE add_player_rating ( p_player_id NUMBER, p_attribute_date DATE, p_overall_rating NUMBER, ) AS CURSOR c_history IS SELECT attribute_date, overall_rating FROM PKAYER_ATTRIBUTE_HISTORY WHERE player_id = p_player_id ORDER BY attribute_date DESC v_history_row c_history%ROWTYPE ; ---BEGIN portion---- BEGIN INSERT INTO PLAYER_ATTRIBUTE_HISTORY (player_id, attribute_date, overall_rating) VALUES (p_player_id, p_attribute_date, p_overall_rating) ; ---DBMS----- DBMS_OUTPUT.PUT_LINE() ll p_player_id) ; DBMS_OUTPUT.PUT_LINE('---------------------------')) ; OPEN c_history; LOOP FETCH c_history INTO v_history_row; EXIT WHEN c_history%NOTFOUND; DBMS_OUTPUT.PUT_LINE ('Date; ' l l TO_CHAR (v_history_row.attribute_date, 'YYYY-MM-DD') l l ' l Rating : ' l l v_history_row.overall_rating); END LOOP; CLOSE c_history --EXCEPTION -- EXCEPTION WHEN OTHERS THEN DBMS_OUTPUT.PUT_LINE ('An errored occurred: ' l l SQLEERM); IF c_history%ISOPEN THEN CLOSE c_history; END IF; ID add_player_rating; | C17: 2.5 | D17: 5 | E17: 3 | F17: 2.5 | G17: 1.5 | H17: =SUM(C17:G17) | I17: Header: 3 params, trailing comma. INSERT correct. Cursor: correct with WHERE and ORDER BY DESC, uses %ROWTYPE. OPEN/FETCH/CLOSE pattern — correct EXIT WHEN. Output: uses "l l" instead of "||" (written on paper), TO_CHAR formatting. "PKAYER" typo. CLOSE c_history missing semicolon. Good exception handling.
A18: Ken Tran | B18: CREATE OR REPLACE PROCEDURE add_player_rating ( p_player_id IN NUMBER, p_attribute_date IN DATE, p_overall_rating IN NUMBER, p_potential IN NUMBER, p_preferred_foot IN VARCHAR 2) AS BEGIN INSERT INTO PLAYER_ATTRIBUTE_HISTORY ( player _attr_id, player_id , attribute_date, overall_rating, potential , preferred_foot) VALUES ( (SELECT MAX(player_attr_id) + 1 FROM PLAYER_ATTRIBUTE_HISTORY), p_player_id , p_attribute_date , p_overall_rating , p_potential , p_preferred_foot); DBMS_OUTPUT.PUT_LINE ('Rating was added for player ID:'|| p_player_id); DECLARE CURSOR c_player_history IS FOR rec IN ( SELECT attribute_date,overall_rating FROM PLAYER_ATTRIBUTE_HISTORY WHERE player_id = p_player_id ORDER BY attribute_date DESC) LOOP DBMS_OUTPUT.PUT_LINE ('Date: || TO_CHAR(rec.attribute_date, 'YYYY - MM -DD')|| 'Rating:' ||rec.overall_rating); END LOOP; CLOSE c_player_history; EXCEPTION WHEN OTHERS THEN RAISE_APPLICATION_ERROR(-20005, 'Error adding player rating: ' ||SQLERM); END; | C18: 3 | D18: 5 | E18: 2.5 | F18: 2.5 | G18: 2 | H18: =SUM(C18:G18) | I18: Header: 5 params including potential and preferred_foot — thorough. INSERT excellent with subquery for PK. Cursor: DECLARE in wrong place (inside BEGIN), mixes FOR LOOP with explicit cursor. Has WHERE and ORDER BY DESC. Output: missing closing quote in TO_CHAR string. CLOSE on cursor that was opened with FOR (wrong). Exception handling present.
A19: Dan Brendza | B19: CREATE OR REPLACE PROCEDURE add_player_rating (p_overall_rating PLAYER_ATTRIBUTE_HISTORY.overall_rating%TYPE, p_attribute_date PLAYER_ATTRIBUTE_HISTORY.attribute_date%TYPE, p_id PLAYER_ATTRIBUTE_HISTORY.player_id%TYPE) AS DECLARE v_rating NUMBER; v_date NUMBER; CURSOR c_ratings IS SELECT attribute_date, overall_rating FROM PLAYER_ATTRIBUTE_HISTORY WHERE player_id = p_id ORDER BY attribute_date DESC; BEGIN INSERT INTO PLAYER_ATTRIBUTE_HISTORY (player_id, overall_rating, attribute_date) VALUES (p_id, p_overall_rating, p_attribute_date); OPEN c_ratings; LOOP FETCH c_ratings INTO v_date, v_rating; EXIT WHEN c_ratings%NOTFOUND dbms_output.put_line(v_date || v_rating); END LOOP; CLOSE c_ratings; END; | C19: 3 | D19: 5 | E19: 3 | F19: 2.5 | G19: 1.5 | H19: =SUM(C19:G19) | I19: Header: %TYPE correctly, 3 good params. DECLARE placement issue but functional. INSERT correct. Cursor: correct with WHERE, ORDER BY DESC. OPEN/FETCH/CLOSE: correct structure, EXIT WHEN missing semicolon. Output: put_line present but missing separator between date and rating.
A20: Aiden Linderman | B20: CREATE OR REPLACE PROCEDURE add_player_rating( p_rating_name VARCHAR; ) IS BEGIN | C20: 0.5 | D20: 0 | E20: 0 | F20: 0 | G20: 0 | H20: =SUM(C20:G20) | I20: Header: only 1 param (p_rating_name VARCHAR). Only IS/BEGIN, nothing else.
A21: Kyle Duong | B21: CREATE OR REPLACE PROCEDURE add_player_rating AS BEGIN END; | C21: 0.5 | D21: 0 | E21: 0 | F21: 0 | G21: 0 | H21: =SUM(C21:G21) | I21: Only header and empty BEGIN/END. No params, no INSERT, no cursor, no output.
A22: Nathan Jalandoni | B22: CREATE OR REPLACE PROCEDURE add_player_rating( p_player_id NUMBER, p_attribute_date DATE, p_overall_rating NUMBER ) IS CURSOR c_ratings IS SELECT attribute_date, overall_rating FROM PLAYER_ATTRIBUTE_HISTORY WHERE player_id = p_player_id ORDER BY attribute _date DESC; BEGIN INSERT INTO PLAYER_ATTRIBUTE_HISTORY (player_id, attribute_date, overall_rating) VALUES (p_player_id, p_attribute_date, p_overall_rating); FOR rec IN c_ratings LOOP DBMS_OUTPUT.PUT_LINE(rec.attribute_date | | ' ' | | rec.overall_rating); END LOOP; END; / | C22: 3 | D22: 5 | E22: 2.5 | F22: 3 | G22: 2 | H22: =SUM(C22:G22) | I22: Header: 3 params correct. INSERT correct. Cursor: has WHERE and ORDER BY but "attribute _date" space typo. FOR LOOP correct. Output: "| |" spacing but both fields present. Clean overall.
... A28: Vanessa Nguyen | B28: CREATE OR REPLACE PROCEDURE add_player_rating(p_attribute_date,p_overall_rating) AS CURSOR rating_history BEGIN INSERT INTO PLAYER_ATTRIBUTE_HISTORY(attribute_date, overall_rating) VALUES(p_attribute_date, p_overall_rating) dbms_output.put_line(' OPEN rating_history; END; / | C28: 1 | D28: 2 | E28: 0.5 | F28: 0 | G28: 0.5 | H28: =SUM(C28:G28) | I28: Header: 2 params without datatypes. INSERT: correct table and 2 columns. Cursor: declared but incomplete (no SELECT). No loop (OPEN present but no FETCH). Output: put_line present but cut off.
A29: Carlos Caro | C29: 0 | D29: 0 | E29: 0 | F29: 0 | G29: 0 | H29: =SUM(C29:G29) | I29: Empty submission.
A30: Ian Kim | B30: -- PROCEDURE CREATE OR REPLACE PROCEDURE add_player_rating( p_player_id NUMBER, p_attribute_date DATE, p_overall_rating NUMBER, ) IS CURSOR rating_cur OS SELECT attribute_date, overall_rating FROM player_attribute_history WHERE player_id = p_player_id ORDER BY attribute_date DESC; BEGIN INSERT INTO player_attribute_history (player_id, attribute_date, overall_rating) VALUES (p_player_id, p_attribute_date, p_overall_rating) FOR rec In rating_cur LOOP DBMS_OUTPUT.PUT_LINE( rec.attribute.date || '-' || rec_overall_rating ); END LOOP; END; / | C30: 3 | D30: 4 | E30: 3 | F30: 2.5 | G30: 1.5 | H30: =SUM(C30:G30) | I30: Header: 3 params correct. INSERT correct. Cursor: "OS" instead of "IS" but correct table, WHERE, ORDER BY DESC. FOR LOOP correct. Output: "rec.attribute.date" (dot instead of underscore), "rec_overall_rating" (underscore instead of dot).
A31: Taylor Lewis | B31: CREATE OR REPLACE PROCEDURE add_player_rating AS BEGIN SELECT player_id, FROM FROM END; PLAYER_ATTRIBUTE_HISTORY(player_attr_id, player_id, attribute_date, overall_rating, potential, preferred_foot) | C31: 0.5 | D31: 0 | E31: 0 | F31: 0 | G31: 0 | H31: =SUM(C31:G31) | I31: Header with no params. BEGIN/SELECT but incomplete — lists table schema at end. No INSERT, no cursor, no output.
A32: Ronald Portillo Quinteros | B32: CREATE OR REPLACE PACKAGE add_player_rating AS PROCEDURE (add_player_rating) AS BEGIN INSERT INTO History(PLAYER_ATTRIBUTE_HISTORY) VALUE(add_player_rating); CURSOR add_player DBMS_OUTPUT.PUT_LINE (r_player.srating || ' | History: ' || r_PLAYER_ATTRIBUTE_HISTORY); END; | C32: 0 | D32: 0.5 | E32: 0.5 | F32: 0 | G32: 0.5 | H32: =SUM(C32:G32) | I32: Creates as PACKAGE not PROCEDURE (wrong construct). INSERT attempted but garbled. Cursor declared but not used properly. Output attempted.
A33: Luis Ibarra | B33: CREATE OR REPLACE PROCEDURE p_player_id NUMBER p_attribute_date DATE, p_overall_rating NUMBER ) IS CURSOR rating_cursor IS SELECT attribute_date, overall_rating FROM player_attribute_histroy WHERE player_id = p_player_id ORDER BY attritubte_date DESC; BEGIN INSERT INTO player_attribute_history (player_id, attrobute_date, overall_rating) VALUES (p_player_id,p_attribute_date, p_overall_rating) FOR rec IN rating_cursor LOOP dbms_output.put_line ( rec.attribute_date || rec.overall_rating); END LOOP: END; / | C33: 2 | D33: 4 | E33: 3 | F33: 3 | G33: 2 | H33: =SUM(C33:G33) | I33: Header: missing procedure name (CREATE OR REPLACE PROCEDURE then params). INSERT correct. Cursor: correct with WHERE and ORDER BY DESC, "histroy" and "attritubte_date" typos. FOR LOOP correct. Output correct with both fields. "END LOOP:" colon instead of semicolon.

Sheet Q16_pkg_team_tools
A1: Q16_pkg_team_tools — 12 points total
A2: Student Name | B2: Response | C2: A. Package specification (4 pts) | D2: B. Package body structure (3 pts) | E2: C. Private helper placement (3 pts) | F2: D. Call from public→private (2 pts) | G2: Total | H2: Notes
A3: Melaud Shalikar | B3: CREATE OR REPLACE PACKAGE pkg_team_utils IS FUNCTION team_label( p_team_id IN NUMBER ) RETURN VARCHAR2; PROCEDURE print_team_message( p_team_id IN NUMBER ); Function count_team_players( p_team_id IN NUMBER ) RETURN NUMBER; END pgk_team_utils; / CREATE OR REPLACE PACKAGE BODY pkg_team_utils IS p_unit_team_id NUMBER := 10; PROCEDURE log_action IS BEGIN NULL; END log_action; FUNCTION team_Label( p_team_id IN NUMBER ) RETURN VARCHAR2 IS BEGIN RETURN NULL; END team_label; Procedure print_team_message( p_team_id IN NUMBER; END/ | C3: 3 | D3: 1 | E3: 3 | F3: 0 | G3: =SUM(C3:F3) | H3: Spec: wrong package name "pkg_team_utils" and "pgk_team_utils" at END, but 3 routines declared (get renamed to team_label). Minor name deviations. Body: starts correctly, log_action private, but body is incomplete - only get_team_label implemented, print_team_message cut off. No call to log_action visible. Spurious variable p_unit_team_id.
A4: Alyssa Kathryn Espino | B4: CREATE OR REPLACE PACKAGE BODY pkg_team_tools IS PROCEDURE log_action IS BEGIN NULL; END log_action; FUNCTION get_team_label(p_team_id IN NUMBER) RETURN VARCHAR2 IS BEGIN RETURN NULL; END get_team_label; PROCEDURE print_team_message(p_team_id IN NUMBER) IS BEGIN log_action; NULL; END print_team_message; FUNCTION count_team_players(p_team_id IN NUMBER) RETURN NUMBER IS BEGIN RETURN NULL; END count_team_players; END pkg_team_tools; | C4: 0 | D4: 3 | E4: 3 | F4: 2 | G4: =SUM(C4:F4) | H4: NO SPEC written — only package body. Body: correct structure with all 3 routines + log_action private. log_action correctly first in body. print_team_message calls log_action. But missing spec entirely.
A5: Alexis Garcia | B5: CREATE OR REPLACE PACKAGE pkg_team_tools | C5: 0 | D5: 0 | E5: 0 | F5: 0 | G5: =SUM(C5:F5) | H5: Only one line: CREATE OR REPLACE PACKAGE pkg_team_tools. Nothing else.
A6: Taylor Gensler | B6: PACKAGE SPECIFICATION CREATE OR REPLACE PACKAGE pkg_team_tools IS FUNCTION get_team_label (p_team_id IN NUMBER) RETURN VARCHAR 2 PROCEDURE print_team_message (p_team_id IN NUMBER); FUNCTION count_team_players(p_team_id IN NUMBER) RETURN NUMBER; RETURN NUMBER ENG pkg_team_tools ) PACKAGE BODY CREATE OR REPLACE PACKAGE BODY pkg_team_tools IS PROCEDURE log_action_msg IN VARCHAR 2 IS RETURN VARCHAR2 PROCEDURE print_team_message(p_team_id IN NUMBER) FUNCTION print_team_message(p_team_id IN NUMBER) IS BEGIN NULL END log_action FUNTION get_team_label(p_team_id IN NUMBER) RETURN VARCHAR2; FUNCTION count team players RETURN NUMBER IS BEGIN RETURN NULL END COUNT TEAM PLAYERS END PKG TOOLS | C6: 2 | D6: 1 | E6: 1 | F6: 0 | G6: =SUM(C6:F6) | H6: Spec: has package name, 3 declarations attempted but missing semicolons, RETURN misplaced, "ENG" instead of END. Body: attempted but very garbled — log_action present but confused with other routines, FUNTION typo, mixing up declarations. No clear call from print_team_message to log_action.
A7: Joey Ha | B7: CREATE OR REPLACE PACKAGE BODY pkg_team_tools AS FUNCTION get_team_label(p_team_id NUMBER) RETURN VARCHAR 2; FUNCTION count_team_players(p_team_id NUMBER) RETURN NUMBER; PROCEDURE print_team_message(p_team_id NUMBER) AS NULL; RETURN; | C7: 0 | D7: 1 | E7: 0 | F7: 0 | G7: =SUM(C7:F7) | H7: Written as PACKAGE BODY only (no spec). Lists declarations but mixes them — has RETURN after procedure. No proper implementations. No log_action. No call.
A8: Nathan Hoang | B8: CREATE OR REPLACE PACKAGE pkg_team_tools FUNCTION get_team_label(p_team_id NUMBER) RETURN varchar2; PROCEDURE print_team_message(p_team_id NUMBER); FUNCTION count_team_players(p_team_id NUMBER) RETURN NUMBER; END pkg_team_tools; CREATE OR REPLACE PACKAGE BODY pkg_team_tools IS PROCEDURE log_action IS BEGIN NULL; END; FUNCTION get_team_label(p_team_id NUMBER) RETURN varchar2 IS BEGIN RETURN NULL; END; PROCEDURE print_team_message(p_team_id NUMBER) IS BEGIN Log_action; NULL; END; FUNCTION count_team_players(p_team_id NUMBER) RETURN NUMBER IS BEGIN RETURN NULL; END; | C8: 3 | D8: 3 | E8: 3 | F8: 2 | G8: =SUM(C8:F8) | H8: Spec: missing IS/AS keyword after package name, but all 3 declarations present. Body: correct structure. log_action private, implemented first. print_team_message calls log_action. All routines implemented. Missing END pkg_team_tools at end of body.
A9: Himanshu Ladole | B9: CREATE OR REPLACE PACKAGE pkg_team_tools AS PROCEDURE log_action ( ); FUNCTION get_team_label ( p_team_id IN NUMBER ) RETURN VARCHAR2; PROCEDURE print_team_message ( p_team_id IN NUMBER ); FUNCTION count_team_players ( p_team_id IN NUMBER ) RETURN NUMBER; END pkg_team_tools; | C9: 2 | D9: 0 | E9: 0 | F9: 0 | G9: =SUM(C9:F9) | H9: Spec: includes log_action (should be private — key error, -2). Has all 3 public routines. No package body at all.
A10: Sydney Mendez | B10: CREATE OR REPLACE PACKAGE pkg_teamtools AS FUNCTION get_team_label(p_team_id IN NUMBER) RETURN VARCHAR2; PROCEDURE print_team_message(p_team_id IN NUMBER); FUNCTION count_team_players(p_team_id IN NUMBER) RETURN NUMBER; END pkg_team_tools; / -- CREATE OR REPLACE PACKAGE BODY pkg_team_tools AS PROCEDURE log_action(p_team_id IN NUMBER) IS BEGIN NULL; END log_action; FUNCTION get_team_label(p_team_id In NUMBER) RETURN VARCHAR2 IS BEGIN RETURN NULL; END get_team_label; PROCEDURE print_team_message(p_team_id IN NUMBER IS BEGIN log_action(p_team_id; END print_team_message; FUNCTION count_team_players(p_team_id IN NUMBER) RETURN NUMBER IS BEGIN RETURN NULL; END count_team_players; END pkg_team_tools; / | C10: 3.5 | D10: 2.5 | E10: 3 | F10: 2 | G10: =SUM(C10:F10) | H10: Spec: "pkg_teamtools" (missing underscore) but all 3 declarations correct. Body: log_action private with param (acceptable), all routines present. print_team_message calls log_action. Missing closing paren in one call. Minor syntax issues.
A11: Celest Moreira | B11: PACKAGE SPECIFICATION: CREATE OR REPLACE PACKAGE pkg_team_tools IS FUNCTION get_team_label(p_team_id IN NUMBER) RETURN VARCHAR2; PROCEDURE print_team_message(p_team_message(p_team_id IN NUMBER); FUNCTION count_team_players(p_team_id IN NUMBER) RETURN NUMBER; ENG pkg_team_tools; / PACKAGE BODY: CREATE OR REPLACE PACKAGE BODY pkg_team_tools IS PROCEDURE log_action(p_msg IN VARCHAR2) IS BEGIN NULL: END log_action; FUNCTION get_team_label (p_team_id IN NUMBER) RETURN VARCHAR2 IS BEGIN RETURN NULL; END get_team_label; PROCEDURE print_team_message (p_team_id IN NUMBER) IS BEGIN log_action('Printing team message:'); NULL: END print_team_message; FUNCTION count_team_players(p_team_id IN NUMBER) RETURN NUMBER IS BEGIN RETURN NULL; END count_team_players; END pkg_team_tools; / | C11: 3 | D11: 3 | E11: 3 | F11: 2 | G11: =SUM(C11:F11) | H11: Spec: "ENG" instead of END, "print_team_message(p_team_message(" double paren typo. Body: correct structure, log_action private with param, called from print_team_message. All routines implemented. Uses "NULL:" instead of "NULL;" (colon).
A12: Michael Nguyen | B12: create or replace package pkg_team_tools as FUNCTION get_team_label(p_team_id IN NUMBER) RETURN VARCHAR2; PROCEDURE print_team_message(p_team_id IN NUMBER); FUNCTION count_team_players(p_team_id IN NUMBER) RETURN NUMBER; end pkg_team_tools; / create or replace package body pkg_team_tools AS Procedure log_action IS BEGIN Null; end; FUNCTION get_team_label(p_team_id IN NUMBER) RETURN VARCHAR2 IS Begin Return NULL; end; PROCEDURE print_team_message(p_team_id IN NUMBER) IS BEGIN log_action; null; end; FUNCTION count_team_players(p_team_id IN NUMBER) RETURN NUMBER IS Begin return null; end; end pkg_team_tools; | C12: 4 | D12: 3 | E12: 3 | F12: 2 | G12: =SUM(C12:F12) | H12: Spec: perfect — all 3 public routines, correct END. Body: all routines implemented with log_action private. print_team_message calls log_action. Clean structure.
